<?xml version="1.0" ?>
<!-- =================================================================================== -->
<!-- |    This document was autogenerated by xacro from r2.urdf                        | -->
<!-- |    EDITING THIS FILE BY HAND IS NOT RECOMMENDED                                 | -->
<!-- =================================================================================== -->
<robot name="r2">
  <material name="darkgrey">
    <color rgba="0.1 0.1 0.1 1.0"/>
  </material>
  <material name="grey">
    <color rgba="0.5 0.5 0.5 1.0"/>
  </material>
  <material name="blue">
    <color rgba="0.0 0.0 0.8 1.0"/>
  </material>
  <link name="base_footprint"/>
  <joint name="base_joint" type="fixed">
    <parent link="base_footprint"/>
    <child link="base_link"/>
    <origin rpy="0 0 0" xyz="0 0 0"/>
  </joint>
  <link name="base_link">
    <visual>
      <origin rpy="0 0 0" xyz="0 0 0"/>
      <geometry>
        <box size="0.44 0.4 0.02"/>
      </geometry>
      <material name="grey"/>
    </visual>
    <collision>
      <origin rpy="0 0 0" xyz="0 0 0"/>
      <geometry>
        <box size="0.44 0.4 0.02"/>
      </geometry>
    </collision>
    <inertial>
      <origin rpy="0.0 0.0 0.0" xyz="0.0 0.0 0.0"/>
      <mass value="1.0"/>
      <inertia ixx="0.01336666666666667" ixy="0" ixz="0" iyy="0.016166666666666666" iyz="0" izz="0.016166666666666666"/>
    </inertial>
  </link>
  <joint name="fl_wheel_joint" type="continuous">
    <parent link="base_link"/>
    <child link="fl_wheel_link"/>
    <origin rpy="0 0 -1.5707963267948966" xyz="-0.19 -0.22 -0.03"/>
    <axis rpy="0 0 0" xyz="1 0 0"/>
  </joint>
  <link name="fl_wheel_link">
    <visual>
      <origin rpy="0 0 0" xyz="0 0 0"/>
      <geometry>
        <mesh filename="package://r2_description/meshes/fl_wheel_link.STL" scale="0.6 0.6 0.6"/>
      </geometry>
      <material name="darkgrey"/>
    </visual>
    <collision>
      <origin rpy="0 0 0" xyz="0 0 0"/>
      <geometry>
        <box size="0.03 0.06 0.06"/>
      </geometry>
    </collision>
    <inertial>
      <origin rpy="0 0 0" xyz="0 0 0"/>
      <mass value="0.5"/>
      <inertia ixx="0.00015" ixy="0" ixz="0" iyy="0.00015" iyz="0" izz="0.000225"/>
    </inertial>
  </link>
  <joint name="fr_wheel_joint" type="continuous">
    <parent link="base_link"/>
    <child link="fr_wheel_link"/>
    <origin rpy="0 0 1.5707963267948966" xyz="-0.19 0.22 -0.03"/>
    <axis rpy="0 0 0" xyz="-1 0 0"/>
  </joint>
  <link name="fr_wheel_link">
    <visual>
      <origin rpy="0 0 0" xyz="0 0 0"/>
      <geometry>
        <mesh filename="package://r2_description/meshes/fr_wheel_link.STL" scale="0.6 0.6 0.6"/>
      </geometry>
      <material name="darkgrey"/>
    </visual>
    <collision>
      <origin rpy="0 0 0" xyz="0 0 0"/>
      <geometry>
        <box size="0.03 0.06 0.06"/>
      </geometry>
    </collision>
    <inertial>
      <origin rpy="0 0 0" xyz="0 0 0"/>
      <mass value="0.5"/>
      <inertia ixx="0.00015" ixy="0" ixz="0" iyy="0.00015" iyz="0" izz="0.000225"/>
    </inertial>
  </link>
  <joint name="rl_wheel_joint" type="continuous">
    <parent link="base_link"/>
    <child link="rl_wheel_link"/>
    <origin rpy="0 0 -1.5707963267948966" xyz="0.19 -0.22 -0.03"/>
    <axis rpy="0 0 0" xyz="1 0 0"/>
  </joint>
  <link name="rl_wheel_link">
    <visual>
      <origin rpy="0 0 0" xyz="0 0 0"/>
      <geometry>
        <mesh filename="package://r2_description/meshes/rl_wheel_link.STL" scale="0.6 0.6 0.6"/>
      </geometry>
      <material name="darkgrey"/>
    </visual>
    <collision>
      <origin rpy="0 0 0" xyz="0 0 0"/>
      <geometry>
        <box size="0.03 0.06 0.06"/>
      </geometry>
    </collision>
    <inertial>
      <origin rpy="0 0 0" xyz="0 0 0"/>
      <mass value="0.5"/>
      <inertia ixx="0.00015" ixy="0" ixz="0" iyy="0.00015" iyz="0" izz="0.000225"/>
    </inertial>
  </link>
  <joint name="rr_wheel_joint" type="continuous">
    <parent link="base_link"/>
    <child link="rr_wheel_link"/>
    <origin rpy="0 0 1.5707963267948966" xyz="0.19 0.22 -0.03"/>
    <axis rpy="0 0 0" xyz="-1 0 0"/>
  </joint>
  <link name="rr_wheel_link">
    <visual>
      <origin rpy="0 0 0" xyz="0 0 0"/>
      <geometry>
        <mesh filename="package://r2_description/meshes/rr_wheel_link.STL" scale="0.6 0.6 0.6"/>
      </geometry>
      <material name="darkgrey"/>
    </visual>
    <collision>
      <origin rpy="0 0 0" xyz="0 0 0"/>
      <geometry>
        <box size="0.03 0.06 0.06"/>
      </geometry>
    </collision>
    <inertial>
      <origin rpy="0 0 0" xyz="0 0 0"/>
      <mass value="0.5"/>
      <inertia ixx="0.00015" ixy="0" ixz="0" iyy="0.00015" iyz="0" izz="0.000225"/>
    </inertial>
  </link>
  <gazebo>
    <plugin filename="libgazebo_ros_planar_move.so" name="planar_move_plugin">
      <robotNamespace>/</robotNamespace>
      <bodyName>base_link</bodyName>
      <commandTopic>cmd_vel</commandTopic>
      <odometryTopic>odom</odometryTopic>
      <odometryFrame>odom</odometryFrame>
      <odometryRate>100.0</odometryRate>
      <robotBaseFrame>base_footprint</robotBaseFrame>
    </plugin>
  </gazebo>
  <joint name="luna_1_joint" type="fixed">
    <parent link="base_link"/>
    <child link="luna_1"/>
    <origin rpy="0 0 0" xyz="0.22 0.1 0"/>
  </joint>
  <link name="luna_1">
    <visual>
      <origin rpy="0 0 0" xyz="0 0 0"/>
      <geometry>
        <box size="0.02 0.03 0.01"/>
      </geometry>
      <material name="blue"/>
    </visual>
    <collision>
      <origin rpy="0 0 0" xyz="0 0 0"/>
      <geometry>
        <box size="0.02 0.03 0.01"/>
      </geometry>
    </collision>
    <inertial>
      <origin rpy="0.0 0.0 0.0" xyz="0.0 0.0 0.0"/>
      <mass value="0.1"/>
      <inertia ixx="8.333333333333334e-06" ixy="0" ixz="0" iyy="4.166666666666667e-06" iyz="0" izz="4.166666666666667e-06"/>
    </inertial>
  </link>
  <joint name="luna_2_joint" type="fixed">
    <parent link="base_link"/>
    <child link="luna_2"/>
    <origin rpy="0 0 0" xyz="0.22 -0.1 0"/>
  </joint>
  <link name="luna_2">
    <visual>
      <origin rpy="0 0 0" xyz="0 0 0"/>
      <geometry>
        <box size="0.02 0.03 0.01"/>
      </geometry>
      <material name="blue"/>
    </visual>
    <collision>
      <origin rpy="0 0 0" xyz="0 0 0"/>
      <geometry>
        <box size="0.02 0.03 0.01"/>
      </geometry>
    </collision>
    <inertial>
      <origin rpy="0.0 0.0 0.0" xyz="0.0 0.0 0.0"/>
      <mass value="0.1"/>
      <inertia ixx="8.333333333333334e-06" ixy="0" ixz="0" iyy="4.166666666666667e-06" iyz="0" izz="4.166666666666667e-06"/>
    </inertial>
  </link>
  <joint name="luna_3_joint" type="fixed">
    <parent link="base_link"/>
    <child link="luna_3"/>
    <origin rpy="0 0 -1.5707963267948966" xyz="0.1 -0.2 0"/>
  </joint>
  <link name="luna_3">
    <visual>
      <origin rpy="0 0 0" xyz="0 0 0"/>
      <geometry>
        <box size="0.02 0.03 0.01"/>
      </geometry>
      <material name="blue"/>
    </visual>
    <collision>
      <origin rpy="0 0 0" xyz="0 0 0"/>
      <geometry>
        <box size="0.02 0.03 0.01"/>
      </geometry>
    </collision>
    <inertial>
      <origin rpy="0.0 0.0 0.0" xyz="0.0 0.0 0.0"/>
      <mass value="0.1"/>
      <inertia ixx="8.333333333333334e-06" ixy="0" ixz="0" iyy="4.166666666666667e-06" iyz="0" izz="4.166666666666667e-06"/>
    </inertial>
  </link>
  <joint name="luna_4_joint" type="fixed">
    <parent link="base_link"/>
    <child link="luna_4"/>
    <origin rpy="0 0 -1.5707963267948966" xyz="-0.1 -0.2 0"/>
  </joint>
  <link name="luna_4">
    <visual>
      <origin rpy="0 0 0" xyz="0 0 0"/>
      <geometry>
        <box size="0.02 0.03 0.01"/>
      </geometry>
      <material name="blue"/>
    </visual>
    <collision>
      <origin rpy="0 0 0" xyz="0 0 0"/>
      <geometry>
        <box size="0.02 0.03 0.01"/>
      </geometry>
    </collision>
    <inertial>
      <origin rpy="0.0 0.0 0.0" xyz="0.0 0.0 0.0"/>
      <mass value="0.1"/>
      <inertia ixx="8.333333333333334e-06" ixy="0" ixz="0" iyy="4.166666666666667e-06" iyz="0" izz="4.166666666666667e-06"/>
    </inertial>
  </link>
  <gazebo reference="luna_1">
    <sensor name="luna_1" type="ray">
      <always_on>true</always_on>
      <visualize>true</visualize>
      <pose>0.0 0 0.0 0 0 0</pose>
      <update_rate>5</update_rate>
      <ray>
        <scan>
          <horizontal>
            <samples>5</samples>
            <resolution>1.0</resolution>
            <min_angle>0</min_angle>
            <max_angle>0</max_angle>
          </horizontal>
          <vertical>
            <samples>5</samples>
            <resolution>1.0</resolution>
            <min_angle>0.0</min_angle>
            <max_angle>0.0</max_angle>
          </vertical>
        </scan>
        <range>
          <min>0.02</min>
          <max>8</max>
          <resolution>0.01</resolution>
        </range>
        <noise>
          <type>gaussian</type>
          <mean>0.0</mean>
          <stddev>0.01</stddev>
        </noise>
      </ray>
      <plugin filename="libgazebo_ros_ray_sensor.so" name="luna_1">
        <ros>
          <namespace>distance</namespace>
          <remapping>~/out:=luna_1</remapping>
        </ros>
        <output_type>sensor_msgs/Range</output_type>
        <radiation_type>ultrasound</radiation_type>
        <frame_name>luna_1_dist_sensor</frame_name>
      </plugin>
    </sensor>
    <material>Gazebo/Blue</material>
  </gazebo>
  <gazebo>
    <sensor name="luna_2" type="ray">
      <always_on>true</always_on>
      <visualize>true</visualize>
      <pose>0.0 0 0.0 0 0 0</pose>
      <update_rate>5</update_rate>
      <ray>
        <scan>
          <horizontal>
            <samples>5</samples>
            <resolution>1.0</resolution>
            <min_angle>0</min_angle>
            <max_angle>0</max_angle>
          </horizontal>
          <vertical>
            <samples>5</samples>
            <resolution>1.0</resolution>
            <min_angle>0.0</min_angle>
            <max_angle>0.0</max_angle>
          </vertical>
        </scan>
        <range>
          <min>0.02</min>
          <max>8</max>
          <resolution>0.01</resolution>
        </range>
        <noise>
          <type>gaussian</type>
          <mean>0.0</mean>
          <stddev>0.01</stddev>
        </noise>
      </ray>
      <plugin filename="libgazebo_ros_ray_sensor.so" name="luna_2">
        <ros>
          <namespace>distance</namespace>
          <remapping>~/out:=luna_2</remapping>
        </ros>
        <output_type>sensor_msgs/Range</output_type>
        <radiation_type>ultrasound</radiation_type>
        <frame_name>luna_2_dist_sensor</frame_name>
      </plugin>
    </sensor>
    <material>Gazebo/Blue</material>
  </gazebo>
  <gazebo>
    <sensor name="luna_3" type="ray">
      <always_on>true</always_on>
      <visualize>true</visualize>
      <pose>0.0 0 0.0 0 0 0</pose>
      <update_rate>5</update_rate>
      <ray>
        <scan>
          <horizontal>
            <samples>5</samples>
            <resolution>1.0</resolution>
            <min_angle>0</min_angle>
            <max_angle>0</max_angle>
          </horizontal>
          <vertical>
            <samples>5</samples>
            <resolution>1.0</resolution>
            <min_angle>0.0</min_angle>
            <max_angle>0.0</max_angle>
          </vertical>
        </scan>
        <range>
          <min>0.02</min>
          <max>8</max>
          <resolution>0.01</resolution>
        </range>
        <noise>
          <type>gaussian</type>
          <mean>0.0</mean>
          <stddev>0.01</stddev>
        </noise>
      </ray>
      <plugin filename="libgazebo_ros_ray_sensor.so" name="luna_3">
        <ros>
          <namespace>distance</namespace>
          <remapping>~/out:=luna_3</remapping>
        </ros>
        <output_type>sensor_msgs/Range</output_type>
        <radiation_type>ultrasound</radiation_type>
        <frame_name>luna_3_dist_sensor</frame_name>
      </plugin>
    </sensor>
    <material>Gazebo/Blue</material>
  </gazebo>
  <gazebo>
    <sensor name="luna_4" type="ray">
      <always_on>true</always_on>
      <visualize>true</visualize>
      <pose>0.0 0 0.0 0 0 0</pose>
      <update_rate>5</update_rate>
      <ray>
        <scan>
          <horizontal>
            <samples>5</samples>
            <resolution>1.0</resolution>
            <min_angle>0</min_angle>
            <max_angle>0</max_angle>
          </horizontal>
          <vertical>
            <samples>5</samples>
            <resolution>1.0</resolution>
            <min_angle>0.0</min_angle>
            <max_angle>0.0</max_angle>
          </vertical>
        </scan>
        <range>
          <min>0.02</min>
          <max>8</max>
          <resolution>0.01</resolution>
        </range>
        <noise>
          <type>gaussian</type>
          <mean>0.0</mean>
          <stddev>0.01</stddev>
        </noise>
      </ray>
      <plugin filename="libgazebo_ros_ray_sensor.so" name="luna_4">
        <ros>
          <namespace>distance</namespace>
          <remapping>~/out:=luna_4</remapping>
        </ros>
        <output_type>sensor_msgs/Range</output_type>
        <radiation_type>ultrasound</radiation_type>
        <frame_name>luna_4_dist_sensor</frame_name>
      </plugin>
    </sensor>
    <material>Gazebo/Blue</material>
  </gazebo>
  <!-- IMU LINK AT CENTER OF ROBOT -->
  <joint name="imu_joint" type="fixed">
    <parent link="base_link"/>
    <child link="imu_link"/>
    <origin rpy="0 0 0" xyz="0 0 0.01"/>
  </joint>
  <link name="imu_link">
    <visual>
      <origin rpy="0 0 0" xyz="0 0 0"/>
      <geometry>
        <box size="0.02 0.02 0.02"/>
      </geometry>
      <material name="grey"/>
    </visual>
    <collision>
      <origin rpy="0 0 0" xyz="0 0 0"/>
      <geometry>
        <box size="0.02 0.02 0.02"/>
      </geometry>
    </collision>
    <inertial>
      <origin rpy="0.0 0.0 0.0" xyz="0.0 0.0 0.0"/>
      <mass value="0.100"/>
      <inertia ixx="6.6666666666666675e-06" ixy="0" ixz="0" iyy="6.6666666666666675e-06" iyz="0" izz="6.6666666666666675e-06"/>
    </inertial>
  </link>
  <gazebo reference="imu_link">
    <sensor name="r2_imu" type="imu">
      <always_on>true</always_on>
      <update_rate>100</update_rate>
      <imu>
        <angular_velocity>
          <x>
            <noise type="gaussian">
              <mean>0.0</mean>
              <stddev>2e-4</stddev>
            </noise>
          </x>
          <y>
            <noise type="gaussian">
              <mean>0.0</mean>
              <stddev>2e-4</stddev>
            </noise>
          </y>
          <z>
            <noise type="gaussian">
              <mean>0.0</mean>
              <stddev>2e-4</stddev>
            </noise>
          </z>
        </angular_velocity>
        <linear_acceleration>
          <x>
            <noise type="gaussian">
              <mean>0.0</mean>
              <stddev>1.7e-2</stddev>
            </noise>
          </x>
          <y>
            <noise type="gaussian">
              <mean>0.0</mean>
              <stddev>1.7e-2</stddev>
            </noise>
          </y>
          <z>
            <noise type="gaussian">
              <mean>0.0</mean>
              <stddev>1.7e-2</stddev>
            </noise>
          </z>
        </linear_acceleration>
      </imu>
      <plugin filename="libgazebo_ros_imu_sensor.so" name="bytes_imu">
        <ros>
          <namespace>imu</namespace>
          <remapping>~/out:=data</remapping>
        </ros>
        <initial_orientation_as_reference>true</initial_orientation_as_reference>
      </plugin>
    </sensor>
  </gazebo>
</robot>
